Workbook

Sheet Sales_raw_data
A1: Order ID | B1: Product ID | C1: Product Name | D1: Category | E1: Region | F1: Sales Channel | G1: Sales Rep | H1: Order Date | I1: Units Sold | J1: Unit Price (₦) | K1: Discount (%) | L1: Payment Status | M1: Total Sales (₦) | N1: Net Revenue (₦) | O1: Revenue Tier
A2: ORD-1001 | B2: PKG-001 | D2: BEVERAGES | E2: NORTH | F2: SUPERMARKET | G2: AMARA OSEI | H2: 45292 | I2: 337 units | J2: ₦990.00 | K2: 0.12 | L2: PAID
A3: ORD-1002 | B3: PKG-002 | D3: Snacks | E3: South | F3: Wholesaler | G3: Tunde Bello | H3: 45293 | I3: 135 | J3: 350 | L3: Pending
A4: ORD-1003 | B4: PKG-003 | D4: Snacks | E4: East | F4: Online | G4: Ngozi Eze | H4: 45294 | I4: 387 | J4: 420 | L4: Paid
A5: ORD-1004 | B5: PKG-004 | D5: Beverages | E5: West | F5: Convenience Store | G5: Emeka Okafor | H5: 45295 | I5: 389 | J5: 1200 | K5: 0.03 | L5: Paid
A6: ORD-1005 | B6: PKG-005 | D6: Beverages | E6: Central | F6: Pharmacy | G6: Fatima Musa | H6: 45296 | I6: 226 | J6: 200 | L6: Pending
A7: ORD-1006 | B7: PKG-006 | D7: Baked Goods | E7: North | F7: Supermarket | G7: Chidi Nwosu | H7: 45297 | J7: 895 | L7: Paid | M7: 89500
A8: ORD-1007 | B8: PKG-007 | D8: Beverages | E8: South | F8: Wholesaler | G8: Amara Osei | H8: 45298 | I8: 268 | J8: 650 | K8: 0.09 | L8: Pending
A9: ORD-1008 | B9: PKG-008 | D9: Breakfast | E9: East | F9: Online | G9: Tunde Bello | H9: 45299 | I9: 376 | J9: 2800 | L9: Paid
A10: ORD-1009 | B10: PKG-009 | D10: Snacks | E10: West | F10: Convenience Store | G10: Ngozi Eze | H10: 45300 | I10: 289 | J10: 280 | L10: Paid
A11: ORD-1010 | B11: PKG-010 | D11: Baked Goods | E11: Central | F11: Pharmacy | G11: Emeka Okafor | H11: 45301 | I11: 239 | J11: 750 | K11: 0.13 | L11: Pending
A12: ORD-1011 | B12: PKG-001 | D12: Beverages | E12: North | F12: Supermarket | G12: Fatima Musa | H12: 45302 | I12: 13 | J12: 990 | L12: Paid
A13: ORD-1011 | B13: PKG-001 | D13: Beverages | E13: North | F13: Supermarket | G13: Fatima Musa | H13: 45303 | I13: 13 | J13: 990 | L13: Paid
A14: ORD-1012 | B14: PKG-002 | D14: Snacks | E14: South | F14: Wholesaler | G14: Chidi Nwosu | H14: 45304 | I14: 91 | J14: 350 | L14: Pending
A15: ORD-1013 | B15: PKG-003 | D15: Snacks | E15: East | F15: Online | G15: Amara Osei | H15: 45305 | I15: 184 | K15: 0.05 | L15: Paid
A16: ORD-1014 | B16: PKG-004 | D16: Beverages | E16: West | F16: Convenience Store | G16: Tunde Bello | H16: 45306 | I16: 400 | J16: 1200 | L16: Paid
A17: ORD-1015 | B17: PKG-005 | D17: Beverages | E17: Central | F17: Pharmacy | G17: Ngozi Eze | H17: 45307 | I17: 57 | J17: 200 | L17: Pending
A18: ORD-1016 | B18: PKG-006 | D18: Baked Goods | E18: North | F18: Supermarket | G18: Emeka Okafor | H18: 45308 | I18: 193 | J18: 895 | K18: 0.1 | L18: Paid
A19: ORD-1017 | B19: PKG-007 | D19: Beverages | E19: South | F19: Wholesaler | G19: Fatima Musa | H19: 45309 | I19: 423 | J19: 650 | L19: Pending
A20: ORD-1018 | B20: PKG-008 | D20: BREAKFAST | E20: EAST | F20: ONLINE | G20: CHIDI NWOSU | H20: 45310 | I20: 245 | J20: 2800 | L20: PAID
A21: ORD-1019 | B21: PKG-009 | D21: Snacks | E21: West | F21: Convenience Store | G21: Amara Osei | H21: 45311 | I21: 482 | J21: 280 | K21: 0.09 | L21: Paid
A22: ORD-1020 | B22: PKG-010 | D22: Baked Goods | E22: Central | F22: Pharmacy | G22: Tunde Bello | H22: 45312 | I22: 434 | J22: ₦750.00 | L22: Pending
A23: ORD-1021 | B23: PKG-001 | D23: Beverages | E23: North | F23: Supermarket | G23: Ngozi Eze | H23: 45313 | I23: 463 | J23: 990 | L23: Paid
A24: ORD-1022 | B24: PKG-002 | D24: Snacks | E24: South | F24: Wholesaler | G24: Emeka Okafor | H24: 45314 | I24: 305 | J24: 350 | K24: 0.03 | L24: Pending
A25: ORD-1023 | B25: PKG-003 | D25: Snacks | E25: East | F25: Online | G25: Fatima Musa | H25: 45315 | J25: 420 | L25: Paid | M25: 63000
A26: ORD-1024 | B26: PKG-004 | D26: beverages | E26: west | F26: convenience store | G26: chidi nwosu | H26: 45316 | I26: 158 | J26: 1200 | L26: paid
A27: ORD-1025 | B27: PKG-005 | D27: Beverages | E27: Central | F27: Pharmacy | G27: Amara Osei | H27: 45317 | I27: 447 | J27: 200 | K27: 0.03 | L27: Pending
A28: ORD-1026 | B28: PKG-006 | D28: Baked Goods | E28: North | F28: Supermarket | G28: Tunde Bello | H28: 45318 | I28: 152 units | J28: 895 | L28: Paid
A29: ORD-1027 | B29: PKG-007 | D29: Beverages | E29: South | F29: Wholesaler | G29: Ngozi Eze | H29: 45319 | I29: 437 | J29: 650 | L29: Pending
A30: ORD-1028 | B30: PKG-008 | D30: Breakfast | E30: East | F30: Online | G30: Emeka Okafor | H30: 45320 | I30: 199 | J30: 2800 | K30: 0.11 | L30: Paid
A31: ORD-1029 | B31: PKG-009 | D31: Snacks | E31: West | F31: Convenience Store | G31: Fatima Musa | H31: 45321 | I31: 369 | J31: 280 | L31: Paid
A32: ORD-1030 | B32: PKG-010 | D32: Baked Goods | E32: Central | F32: Pharmacy | G32: Chidi Nwosu | H32: 45322 | I32: 341 | J32: 750 | L32: Pending
A33: ORD-1031 | B33: PKG-001 | D33: Beverages | E33: North | F33: Supermarket | G33: Amara Osei | H33: 45323 | I33: 335 | J33: 990 | K33: 0.11 | L33: Paid
A34: ORD-1032 | B34: PKG-002 | D34: Snacks | E34: South | F34: Wholesaler | G34: Tunde Bello | H34: 45324 | I34: 93 | J34: 350 | L34: Pending
A35: ORD-1033 | B35: PKG-003 | D35: Snacks | E35: East | F35: Online | G35: Ngozi Eze | H35: 45325 | I35: 148 | J35: 420 | L35: Paid
A36: ORD-1034 | B36: PKG-004 | D36: Beverages | E36: West | F36: Convenience Store | G36: Emeka Okafor | H36: 45326 | I36: 337 | J36: 1200 | K36: 0.05 | L36: Paid
A37: ORD-1035 | B37: PKG-005 | D37: BEVERAGES | E37: CENTRAL | F37: PHARMACY | G37: FATIMA MUSA | H37: 45327 | I37: 176 | J37: 200 | L37: PENDING
A38: ORD-1036 | B38: PKG-006 | D38: Baked Goods | E38: North | F38: Supermarket | G38: Chidi Nwosu | H38: 45328 | I38: 407 | J38: 895 | L38: Paid
A39: ORD-1037 | B39: PKG-007 | D39: Beverages | E39: South | F39: Wholesaler | G39: Amara Osei | H39: 45329 | I39: 430 | J39: 650 | K39: 0.06 | L39: Pending
A40: ORD-1038 | B40: PKG-008 | D40: Breakfast | E40: East | F40: Online | G40: Tunde Bello | H40: 45330 | I40: 147 | J40: 2800 | L40: Paid
...

Sheet Product_Lookup
A1: Product ID | B1: Product Name | C1: Category | D1: Unit Price (₦) | E1: Category Code
A2: PKG-009 | B2: CrispBite Corn Chips 100g | C2: Snacks | D2: 280 | E2: SNK
A3: PKG-003 | B3: CrispBite Potato Chips 150g | C3: Snacks | D3: 420 | E3: SNK
A4: PKG-004 | B4: DailyBrew Green Tea 25 bags | C4: Beverages | D4: 1200 | E4: BEV
A5: PKG-007 | B5: FreshSip Mango Juice 500ml | C5: Beverages | D5: 650 | E5: BEV
A6: PKG-001 | B6: FreshSip Orange Juice 1L | C6: Beverages | D6: 990 | E6: BEV
A7: PKG-006 | B7: GoldenBite Biscuits 200g | C7: Baked Goods | D7: 895 | E7: BAK
A8: PKG-010 | B8: GoldenBite Chocolate Cookies 150g | C8: Baked Goods | D8: 750 | E8: BAK
A9: PKG-005 | B9: HealthPure Bottled Water 500ml | C9: Beverages | D9: 200 | E9: BEV
A10: PKG-008 | B10: NutriMix Cereal Box 500g | C10: Breakfast | D10: 2800 | E10: BRK
A11: PKG-002 | B11: NutriMix Granola Bar | C11: Snacks | D11: 350 | E11: SNK
A12: PKG-011 | B12: NouraMart Protein Bar 60g | C12: Snacks | D12: 680 | E12: SNK
A13: PKG-012 | B13: ZestSip Citrus Drink 350ml | C13: Beverages | D13: 450 | E13: BEV
A14: PKG-013 | B14: GoldenBite Oat Cookies 180g | C14: Baked Goods | D14: 820 | E14: BAK

Sheet Clean_data
A1: Order ID | B1: Product ID | C1: Product Name | D1: Category | E1: Region | F1: Sales Channel | G1: Sales Rep | H1: Order Date | I1: Units Sold | J1: Unit Price (₦) | K1: Discount (%) | L1: Payment Status | M1: Total Sales (₦) | N1: Net Revenue (₦) | O1: Revenue Tier
A2: ORD-1001 | B2: PKG-001 | C2: FreshSip Orange Juice 1L | D2: Beverages | E2: North | F2: Supermarket | G2: Amara Osei | H2: 45292 | I2: 337 | J2: 990 | K2: 0.12 | L2: Paid | M2: =old_data[[#This Row],[Units Sold]]*old_data[[#This Row],[Unit Price (₦)]] -> 333630 | N2: =old_data[[#This Row],[Total Sales (₦)]]*(1-old_data[[#This Row],[Discount (%)]]) -> 293594.4 | O2: =IF(old_data[[#This Row],[Net Revenue (₦)]]>350000,"High",IF(old_data[[#This Row],[Net Revenue (₦)]]>100000,"Medium","Low")) -> Medium
A3: ORD-1002 | B3: PKG-002 | C3: NutriMix Granola Bar | D3: Snacks | E3: South | F3: Wholesaler | G3: Tunde Bello | H3: 45293 | I3: 135 | J3: 350 | K3: 0 | L3: Pending | M3: =old_data[[#This Row],[Units Sold]]*old_data[[#This Row],[Unit Price (₦)]] -> 47250 | N3: =old_data[[#This Row],[Total Sales (₦)]]*(1-old_data[[#This Row],[Discount (%)]]) -> 47250 | O3: =IF(old_data[[#This Row],[Net Revenue (₦)]]>350000,"High",IF(old_data[[#This Row],[Net Revenue (₦)]]>100000,"Medium","Low")) -> Low
A4: ORD-1003 | B4: PKG-003 | C4: CrispBite Potato Chips 150g | D4: Snacks | E4: East | F4: Online | G4: Ngozi Eze | H4: 45294 | I4: 387 | J4: 420 | K4: 0 | L4: Paid | M4: =old_data[[#This Row],[Units Sold]]*old_data[[#This Row],[Unit Price (₦)]] -> 162540 | N4: =old_data[[#This Row],[Total Sales (₦)]]*(1-old_data[[#This Row],[Discount (%)]]) -> 162540 | O4: =IF(old_data[[#This Row],[Net Revenue (₦)]]>350000,"High",IF(old_data[[#This Row],[Net Revenue (₦)]]>100000,"Medium","Low")) -> Medium
A5: ORD-1004 | B5: PKG-004 | C5: DailyBrew Green Tea 25 bags | D5: Beverages | E5: West | F5: Convenience Store | G5: Emeka Okafor | H5: 45295 | I5: 389 | J5: 1200 | K5: 0.03 | L5: Paid | M5: =old_data[[#This Row],[Units Sold]]*old_data[[#This Row],[Unit Price (₦)]] -> 466800 | N5: =old_data[[#This Row],[Total Sales (₦)]]*(1-old_data[[#This Row],[Discount (%)]]) -> 452796 | O5: =IF(old_data[[#This Row],[Net Revenue (₦)]]>350000,"High",IF(old_data[[#This Row],[Net Revenue (₦)]]>100000,"Medium","Low")) -> High
A6: ORD-1005 | B6: PKG-005 | C6: HealthPure Bottled Water 500ml | D6: Beverages | E6: Central | F6: Pharmacy | G6: Fatima Musa | H6: 45296 | I6: 226 | J6: 200 | K6: 0 | L6: Pending | M6: =old_data[[#This Row],[Units Sold]]*old_data[[#This Row],[Unit Price (₦)]] -> 45200 | N6: =old_data[[#This Row],[Total Sales (₦)]]*(1-old_data[[#This Row],[Discount (%)]]) -> 45200 | O6: =IF(old_data[[#This Row],[Net Revenue (₦)]]>350000,"High",IF(old_data[[#This Row],[Net Revenue (₦)]]>100000,"Medium","Low")) -> Low
A7: ORD-1006 | B7: PKG-006 | C7: GoldenBite Biscuits 200g | D7: Baked Goods | E7: North | F7: Supermarket | G7: Chidi Nwosu | H7: 45297 | I7: 100 | J7: 895 | K7: 0 | L7: Paid | M7: 89500 | N7: =old_data[[#This Row],[Total Sales (₦)]]*(1-old_data[[#This Row],[Discount (%)]]) -> 89500 | O7: =IF(old_data[[#This Row],[Net Revenue (₦)]]>350000,"High",IF(old_data[[#This Row],[Net Revenue (₦)]]>100000,"Medium","Low")) -> Low
A8: ORD-1007 | B8: PKG-007 | C8: FreshSip Mango Juice 500ml | D8: Beverages | E8: South | F8: Wholesaler | G8: Amara Osei | H8: 45298 | I8: 268 | J8: 650 | K8: 0.09 | L8: Pending | M8: =old_data[[#This Row],[Units Sold]]*old_data[[#This Row],[Unit Price (₦)]] -> 174200 | N8: =old_data[[#This Row],[Total Sales (₦)]]*(1-old_data[[#This Row],[Discount (%)]]) -> 158522 | O8: =IF(old_data[[#This Row],[Net Revenue (₦)]]>350000,"High",IF(old_data[[#This Row],[Net Revenue (₦)]]>100000,"Medium","Low")) -> Medium
A9: ORD-1008 | B9: PKG-008 | C9: NutriMix Cereal Box 500g | D9: Breakfast | E9: East | F9: Online | G9: Tunde Bello | H9: 45299 | I9: 376 | J9: 2800 | K9: 0 | L9: Paid | M9: =old_data[[#This Row],[Units Sold]]*old_data[[#This Row],[Unit Price (₦)]] -> 1052800 | N9: =old_data[[#This Row],[Total Sales (₦)]]*(1-old_data[[#This Row],[Discount (%)]]) -> 1052800 | O9: =IF(old_data[[#This Row],[Net Revenue (₦)]]>350000,"High",IF(old_data[[#This Row],[Net Revenue (₦)]]>100000,"Medium","Low")) -> High
A10: ORD-1009 | B10: PKG-009 | C10: CrispBite Corn Chips 100g | D10: Snacks | E10: West | F10: Convenience Store | G10: Ngozi Eze | H10: 45300 | I10: 289 | J10: 280 | K10: 0 | L10: Paid | M10: =old_data[[#This Row],[Units Sold]]*old_data[[#This Row],[Unit Price (₦)]] -> 80920 | N10: =old_data[[#This Row],[Total Sales (₦)]]*(1-old_data[[#This Row],[Discount (%)]]) -> 80920 | O10: =IF(old_data[[#This Row],[Net Revenue (₦)]]>350000,"High",IF(old_data[[#This Row],[Net Revenue (₦)]]>100000,"Medium","Low")) -> Low
A11: ORD-1010 | B11: PKG-010 | C11: GoldenBite Chocolate Cookies 150g | D11: Baked Goods | E11: Central | F11: Pharmacy | G11: Emeka Okafor | H11: 45301 | I11: 239 | J11: 750 | K11: 0.13 | L11: Pending | M11: =old_data[[#This Row],[Units Sold]]*old_data[[#This Row],[Unit Price (₦)]] -> 179250 | N11: =old_data[[#This Row],[Total Sales (₦)]]*(1-old_data[[#This Row],[Discount (%)]]) -> 155947.5 | O11: =IF(old_data[[#This Row],[Net Revenue (₦)]]>350000,"High",IF(old_data[[#This Row],[Net Revenue (₦)]]>100000,"Medium","Low")) -> Medium
A12: ORD-1011 | B12: PKG-001 | C12: FreshSip Orange Juice 1L | D12: Beverages | E12: North | F12: Supermarket | G12: Fatima Musa | H12: 45302 | I12: 13 | J12: 990 | K12: 0 | L12: Paid | M12: =old_data[[#This Row],[Units Sold]]*old_data[[#This Row],[Unit Price (₦)]] -> 12870 | N12: =old_data[[#This Row],[Total Sales (₦)]]*(1-old_data[[#This Row],[Discount (%)]]) -> 12870 | O12: =IF(old_data[[#This Row],[Net Revenue (₦)]]>350000,"High",IF(old_data[[#This Row],[Net Revenue (₦)]]>100000,"Medium","Low")) -> Low
A13: ORD-1012 | B13: PKG-002 | C13: NutriMix Granola Bar | D13: Snacks | E13: South | F13: Wholesaler | G13: Chidi Nwosu | H13: 45304 | I13: 91 | J13: 350 | K13: 0 | L13: Pending | M13: =old_data[[#This Row],[Units Sold]]*old_data[[#This Row],[Unit Price (₦)]] -> 31850 | N13: =old_data[[#This Row],[Total Sales (₦)]]*(1-old_data[[#This Row],[Discount (%)]]) -> 31850 | O13: =IF(old_data[[#This Row],[Net Revenue (₦)]]>350000,"High",IF(old_data[[#This Row],[Net Revenue (₦)]]>100000,"Medium","Low")) -> Low
A14: ORD-1013 | B14: PKG-003 | C14: CrispBite Potato Chips 150g | D14: Snacks | E14: East | F14: Online | G14: Amara Osei | H14: 45305 | I14: 184 | J14: 420 | K14: 0.05 | L14: Paid | M14: =old_data[[#This Row],[Units Sold]]*old_data[[#This Row],[Unit Price (₦)]] -> 77280 | N14: =old_data[[#This Row],[Total Sales (₦)]]*(1-old_data[[#This Row],[Discount (%)]]) -> 73416 | O14: =IF(old_data[[#This Row],[Net Revenue (₦)]]>350000,"High",IF(old_data[[#This Row],[Net Revenue (₦)]]>100000,"Medium","Low")) -> Low
A15: ORD-1014 | B15: PKG-004 | C15: DailyBrew Green Tea 25 bags | D15: Beverages | E15: West | F15: Convenience Store | G15: Tunde Bello | H15: 45306 | I15: 400 | J15: 1200 | K15: 0 | L15: Paid | M15: =old_data[[#This Row],[Units Sold]]*old_data[[#This Row],[Unit Price (₦)]] -> 480000 | N15: =old_data[[#This Row],[Total Sales (₦)]]*(1-old_data[[#This Row],[Discount (%)]]) -> 480000 | O15: =IF(old_data[[#This Row],[Net Revenue (₦)]]>350000,"High",IF(old_data[[#This Row],[Net Revenue (₦)]]>100000,"Medium","Low")) -> High
A16: ORD-1015 | B16: PKG-005 | C16: HealthPure Bottled Water 500ml | D16: Beverages | E16: Central | F16: Pharmacy | G16: Ngozi Eze | H16: 45307 | I16: 57 | J16: 200 | K16: 0 | L16: Pending | M16: =old_data[[#This Row],[Units Sold]]*old_data[[#This Row],[Unit Price (₦)]] -> 11400 | N16: =old_data[[#This Row],[Total Sales (₦)]]*(1-old_data[[#This Row],[Discount (%)]]) -> 11400 | O16: =IF(old_data[[#This Row],[Net Revenue (₦)]]>350000,"High",IF(old_data[[#This Row],[Net Revenue (₦)]]>100000,"Medium","Low")) -> Low
A17: ORD-1016 | B17: PKG-006 | C17: GoldenBite Biscuits 200g | D17: Baked Goods | E17: North | F17: Supermarket | G17: Emeka Okafor | H17: 45308 | I17: 193 | J17: 895 | K17: 0.1 | L17: Paid | M17: =old_data[[#This Row],[Units Sold]]*old_data[[#This Row],[Unit Price (₦)]] -> 172735 | N17: =old_data[[#This Row],[Total Sales (₦)]]*(1-old_data[[#This Row],[Discount (%)]]) -> 155461.5 | O17: =IF(old_data[[#This Row],[Net Revenue (₦)]]>350000,"High",IF(old_data[[#This Row],[Net Revenue (₦)]]>100000,"Medium","Low")) -> Medium
A18: ORD-1017 | B18: PKG-007 | C18: FreshSip Mango Juice 500ml | D18: Beverages | E18: South | F18: Wholesaler | G18: Fatima Musa | H18: 45309 | I18: 423 | J18: 650 | K18: 0 | L18: Pending | M18: =old_data[[#This Row],[Units Sold]]*old_data[[#This Row],[Unit Price (₦)]] -> 274950 | N18: =old_data[[#This Row],[Total Sales (₦)]]*(1-old_data[[#This Row],[Discount (%)]]) -> 274950 | O18: =IF(old_data[[#This Row],[Net Revenue (₦)]]>350000,"High",IF(old_data[[#This Row],[Net Revenue (₦)]]>100000,"Medium","Low")) -> Medium
A19: ORD-1018 | B19: PKG-008 | C19: NutriMix Cereal Box 500g | D19: Breakfast | E19: East | F19: Online | G19: Chidi Nwosu | H19: 45310 | I19: 245 | J19: 2800 | K19: 0 | L19: Paid | M19: =old_data[[#This Row],[Units Sold]]*old_data[[#This Row],[Unit Price (₦)]] -> 686000 | N19: =old_data[[#This Row],[Total Sales (₦)]]*(1-old_data[[#This Row],[Discount (%)]]) -> 686000 | O19: =IF(old_data[[#This Row],[Net Revenue (₦)]]>350000,"High",IF(old_data[[#This Row],[Net Revenue (₦)]]>100000,"Medium","Low")) -> High
... A23: ORD-1022 | B23: PKG-002 | C23: NutriMix Granola Bar | D23: Snacks | E23: South | F23: Wholesaler | G23: Emeka Okafor | H23: 45314 | I23: 305 | J23: 350 | K23: 0.03 | L23: Pending | M23: =old_data[[#This Row],[Units Sold]]*old_data[[#This Row],[Unit Price (₦)]] -> 106750 | N23: =old_data[[#This Row],[Total Sales (₦)]]*(1-old_data[[#This Row],[Discount (%)]]) -> 103547.5 | O23: =IF(old_data[[#This Row],[Net Revenue (₦)]]>350000,"High",IF(old_data[[#This Row],[Net Revenue (₦)]]>100000,"Medium","Low")) -> Medium
A24: ORD-1023 | B24: PKG-003 | C24: CrispBite Potato Chips 150g | D24: Snacks | E24: East | F24: Online | G24: Fatima Musa | H24: 45315 | I24: 150 | J24: 420 | K24: 0 | L24: Paid | M24: 63000 | N24: =old_data[[#This Row],[Total Sales (₦)]]*(1-old_data[[#This Row],[Discount (%)]]) -> 63000 | O24: =IF(old_data[[#This Row],[Net Revenue (₦)]]>350000,"High",IF(old_data[[#This Row],[Net Revenue (₦)]]>100000,"Medium","Low")) -> Low
A25: ORD-1024 | B25: PKG-004 | C25: DailyBrew Green Tea 25 bags | D25: Beverages | E25: West | F25: Convenience Store | G25: Chidi Nwosu | H25: 45316 | I25: 158 | J25: 1200 | K25: 0 | L25: Paid | M25: =old_data[[#This Row],[Units Sold]]*old_data[[#This Row],[Unit Price (₦)]] -> 189600 | N25: =old_data[[#This Row],[Total Sales (₦)]]*(1-old_data[[#This Row],[Discount (%)]]) -> 189600 | O25: =IF(old_data[[#This Row],[Net Revenue (₦)]]>350000,"High",IF(old_data[[#This Row],[Net Revenue (₦)]]>100000,"Medium","Low")) -> Medium
A26: ORD-1025 | B26: PKG-005 | C26: HealthPure Bottled Water 500ml | D26: Beverages | E26: Central | F26: Pharmacy | G26: Amara Osei | H26: 45317 | I26: 447 | J26: 200 | K26: 0.03 | L26: Pending | M26: =old_data[[#This Row],[Units Sold]]*old_data[[#This Row],[Unit Price (₦)]] -> 89400 | N26: =old_data[[#This Row],[Total Sales (₦)]]*(1-old_data[[#This Row],[Discount (%)]]) -> 86718 | O26: =IF(old_data[[#This Row],[Net Revenue (₦)]]>350000,"High",IF(old_data[[#This Row],[Net Revenue (₦)]]>100000,"Medium","Low")) -> Low
A27: ORD-1026 | B27: PKG-006 | C27: GoldenBite Biscuits 200g | D27: Baked Goods | E27: North | F27: Supermarket | G27: Tunde Bello | H27: 45318 | I27: 152 | J27: 895 | K27: 0 | L27: Paid | M27: =old_data[[#This Row],[Units Sold]]*old_data[[#This Row],[Unit Price (₦)]] -> 136040 | N27: =old_data[[#This Row],[Total Sales (₦)]]*(1-old_data[[#This Row],[Discount (%)]]) -> 136040 | O27: =IF(old_data[[#This Row],[Net Revenue (₦)]]>350000,"High",IF(old_data[[#This Row],[Net Revenue (₦)]]>100000,"Medium","Low")) -> Medium
A28: ORD-1027 | B28: PKG-007 | C28: FreshSip Mango Juice 500ml | D28: Beverages | E28: South | F28: Wholesaler | G28: Ngozi Eze | H28: 45319 | I28: 437 | J28: 650 | K28: 0 | L28: Pending | M28: =old_data[[#This Row],[Units Sold]]*old_data[[#This Row],[Unit Price (₦)]] -> 284050 | N28: =old_data[[#This Row],[Total Sales (₦)]]*(1-old_data[[#This Row],[Discount (%)]]) -> 284050 | O28: =IF(old_data[[#This Row],[Net Revenue (₦)]]>350000,"High",IF(old_data[[#This Row],[Net Revenue (₦)]]>100000,"Medium","Low")) -> Medium
A29: ORD-1028 | B29: PKG-008 | C29: NutriMix Cereal Box 500g | D29: Breakfast | E29: East | F29: Online | G29: Emeka Okafor | H29: 45320 | I29: 199 | J29: 2800 | K29: 0.11 | L29: Paid | M29: =old_data[[#This Row],[Units Sold]]*old_data[[#This Row],[Unit Price (₦)]] -> 557200 | N29: =old_data[[#This Row],[Total Sales (₦)]]*(1-old_data[[#This Row],[Discount (%)]]) -> 495908 | O29: =IF(old_data[[#This Row],[Net Revenue (₦)]]>350000,"High",IF(old_data[[#This Row],[Net Revenue (₦)]]>100000,"Medium","Low")) -> High
A30: ORD-1029 | B30: PKG-009 | C30: CrispBite Corn Chips 100g | D30: Snacks | E30: West | F30: Convenience Store | G30: Fatima Musa | H30: 45321 | I30: 369 | J30: 280 | K30: 0 | L30: Paid | M30: =old_data[[#This Row],[Units Sold]]*old_data[[#This Row],[Unit Price (₦)]] -> 103320 | N30: =old_data[[#This Row],[Total Sales (₦)]]*(1-old_data[[#This Row],[Discount (%)]]) -> 103320 | O30: =IF(old_data[[#This Row],[Net Revenue (₦)]]>350000,"High",IF(old_data[[#This Row],[Net Revenue (₦)]]>100000,"Medium","Low")) -> Medium
A31: ORD-1030 | B31: PKG-010 | C31: GoldenBite Chocolate Cookies 150g | D31: Baked Goods | E31: Central | F31: Pharmacy | G31: Chidi Nwosu | H31: 45322 | I31: 341 | J31: 750 | K31: 0 | L31: Pending | M31: =old_data[[#This Row],[Units Sold]]*old_data[[#This Row],[Unit Price (₦)]] -> 255750 | N31: =old_data[[#This Row],[Total Sales (₦)]]*(1-old_data[[#This Row],[Discount (%)]]) -> 255750 | O31: =IF(old_data[[#This Row],[Net Revenue (₦)]]>350000,"High",IF(old_data[[#This Row],[Net Revenue (₦)]]>100000,"Medium","Low")) -> Medium
A32: ORD-1031 | B32: PKG-001 | C32: FreshSip Orange Juice 1L | D32: Beverages | E32: North | F32: Supermarket | G32: Amara Osei | H32: 45323 | I32: 335 | J32: 990 | K32: 0.11 | L32: Paid | M32: =old_data[[#This Row],[Units Sold]]*old_data[[#This Row],[Unit Price (₦)]] -> 331650 | N32: =old_data[[#This Row],[Total Sales (₦)]]*(1-old_data[[#This Row],[Discount (%)]]) -> 295168.5 | O32: =IF(old_data[[#This Row],[Net Revenue (₦)]]>350000,"High",IF(old_data[[#This Row],[Net Revenue (₦)]]>100000,"Medium","Low")) -> Medium
A33: ORD-1032 | B33: PKG-002 | C33: NutriMix Granola Bar | D33: Snacks | E33: South | F33: Wholesaler | G33: Tunde Bello | H33: 45324 | I33: 93 | J33: 350 | K33: 0 | L33: Pending | M33: =old_data[[#This Row],[Units Sold]]*old_data[[#This Row],[Unit Price (₦)]] -> 32550 | N33: =old_data[[#This Row],[Total Sales (₦)]]*(1-old_data[[#This Row],[Discount (%)]]) -> 32550 | O33: =IF(old_data[[#This Row],[Net Revenue (₦)]]>350000,"High",IF(old_data[[#This Row],[Net Revenue (₦)]]>100000,"Medium","Low")) -> Low
A34: ORD-1033 | B34: PKG-003 | C34: CrispBite Potato Chips 150g | D34: Snacks | E34: East | F34: Online | G34: Ngozi Eze | H34: 45325 | I34: 148 | J34: 420 | K34: 0 | L34: Paid | M34: =old_data[[#This Row],[Units Sold]]*old_data[[#This Row],[Unit Price (₦)]] -> 62160 | N34: =old_data[[#This Row],[Total Sales (₦)]]*(1-old_data[[#This Row],[Discount (%)]]) -> 62160 | O34: =IF(old_data[[#This Row],[Net Revenue (₦)]]>350000,"High",IF(old_data[[#This Row],[Net Revenue (₦)]]>100000,"Medium","Low")) -> Low
A35: ORD-1034 | B35: PKG-004 | C35: DailyBrew Green Tea 25 bags | D35: Beverages | E35: West | F35: Convenience Store | G35: Emeka Okafor | H35: 45326 | I35: 337 | J35: 1200 | K35: 0.05 | L35: Paid | M35: =old_data[[#This Row],[Units Sold]]*old_data[[#This Row],[Unit Price (₦)]] -> 404400 | N35: =old_data[[#This Row],[Total Sales (₦)]]*(1-old_data[[#This Row],[Discount (%)]]) -> 384180 | O35: =IF(old_data[[#This Row],[Net Revenue (₦)]]>350000,"High",IF(old_data[[#This Row],[Net Revenue (₦)]]>100000,"Medium","Low")) -> High
A36: ORD-1035 | B36: PKG-005 | C36: HealthPure Bottled Water 500ml | D36: Beverages | E36: Central | F36: Pharmacy | G36: Fatima Musa | H36: 45327 | I36: 176 | J36: 200 | K36: 0 | L36: Pending | M36: =old_data[[#This Row],[Units Sold]]*old_data[[#This Row],[Unit Price (₦)]] -> 35200 | N36: =old_data[[#This Row],[Total Sales (₦)]]*(1-old_data[[#This Row],[Discount (%)]]) -> 35200 | O36: =IF(old_data[[#This Row],[Net Revenue (₦)]]>350000,"High",IF(old_data[[#This Row],[Net Revenue (₦)]]>100000,"Medium","Low")) -> Low
... A39: ORD-1038 | B39: PKG-008 | C39: NutriMix Cereal Box 500g | D39: Breakfast | E39: East | F39: Online | G39: Tunde Bello | H39: 45330 | I39: 147 | J39: 2800 | K39: 0 | L39: Paid | M39: =old_data[[#This Row],[Units Sold]]*old_data[[#This Row],[Unit Price (₦)]] -> 411600 | N39: =old_data[[#This Row],[Total Sales (₦)]]*(1-old_data[[#This Row],[Discount (%)]]) -> 411600 | O39: =IF(old_data[[#This Row],[Net Revenue (₦)]]>350000,"High",IF(old_data[[#This Row],[Net Revenue (₦)]]>100000,"Medium","Low")) -> High
A40: ORD-1039 | B40: PKG-009 | C40: CrispBite Corn Chips 100g | D40: Snacks | E40: West | F40: Convenience Store | G40: Ngozi Eze | H40: 45331 | I40: 63 | J40: 280 | K40: 0 | L40: Paid | M40: 17640 | N40: =old_data[[#This Row],[Total Sales (₦)]]*(1-old_data[[#This Row],[Discount (%)]]) -> 17640 | O40: =IF(old_data[[#This Row],[Net Revenue (₦)]]>350000,"High",IF(old_data[[#This Row],[Net Revenue (₦)]]>100000,"Medium","Low")) -> Low
A41: ORD-1040 | B41: PKG-010 | C41: GoldenBite Chocolate Cookies 150g | D41: Baked Goods | E41: Central | F41: Pharmacy | G41: Emeka Okafor | H41: 45332 | I41: 458 | J41: 750 | K41: 0.05 | L41: Pending | M41: =old_data[[#This Row],[Units Sold]]*old_data[[#This Row],[Unit Price (₦)]] -> 343500 | N41: =old_data[[#This Row],[Total Sales (₦)]]*(1-old_data[[#This Row],[Discount (%)]]) -> 326325 | O41: =IF(old_data[[#This Row],[Net Revenue (₦)]]>350000,"High",IF(old_data[[#This Row],[Net Revenue (₦)]]>100000,"Medium","Low")) -> Medium
A42: ORD-1041 | B42: PKG-001 | C42: FreshSip Orange Juice 1L | D42: Beverages | E42: North | F42: Supermarket | G42: Fatima Musa | H42: 45333 | I42: 265 | J42: 990 | K42: 0 | L42: Paid | M42: =old_data[[#This Row],[Units Sold]]*old_data[[#This Row],[Unit Price (₦)]] -> 262350 | N42: =old_data[[#This Row],[Total Sales (₦)]]*(1-old_data[[#This Row],[Discount (%)]]) -> 262350 | O42: =IF(old_data[[#This Row],[Net Revenue (₦)]]>350000,"High",IF(old_data[[#This Row],[Net Revenue (₦)]]>100000,"Medium","Low")) -> Medium
A43: ORD-1042 | B43: PKG-002 | C43: NutriMix Granola Bar | D43: Snacks | E43: South | F43: Wholesaler | G43: Chidi Nwosu | H43: 45334 | I43: 478 | J43: 350 | K43: 0 | L43: Pending | M43: =old_data[[#This Row],[Units Sold]]*old_data[[#This Row],[Unit Price (₦)]] -> 167300 | N43: =old_data[[#This Row],[Total Sales (₦)]]*(1-old_data[[#This Row],[Discount (%)]]) -> 167300 | O43: =IF(old_data[[#This Row],[Net Revenue (₦)]]>350000,"High",IF(old_data[[#This Row],[Net Revenue (₦)]]>100000,"Medium","Low")) -> Medium
A44: ORD-1043 | B44: PKG-003 | C44: CrispBite Potato Chips 150g | D44: Snacks | E44: East | F44: Online | G44: Amara Osei | H44: 45335 | I44: 83 | J44: 420 | K44: 0.05 | L44: Paid | M44: =old_data[[#This Row],[Units Sold]]*old_data[[#This Row],[Unit Price (₦)]] -> 34860 | N44: =old_data[[#This Row],[Total Sales (₦)]]*(1-old_data[[#This Row],[Discount (%)]]) -> 33117 | O44: =IF(old_data[[#This Row],[Net Revenue (₦)]]>350000,"High",IF(old_data[[#This Row],[Net Revenue (₦)]]>100000,"Medium","Low")) -> Low
A45: ORD-1044 | B45: PKG-004 | C45: DailyBrew Green Tea 25 bags | D45: Beverages | E45: West | F45: Convenience Store | G45: Tunde Bello | H45: 45336 | I45: 297 | J45: 1200 | K45: 0 | L45: Paid | M45: =old_data[[#This Row],[Units Sold]]*old_data[[#This Row],[Unit Price (₦)]] -> 356400 | N45: =old_data[[#This Row],[Total Sales (₦)]]*(1-old_data[[#This Row],[Discount (%)]]) -> 356400 | O45: =IF(old_data[[#This Row],[Net Revenue (₦)]]>350000,"High",IF(old_data[[#This Row],[Net Revenue (₦)]]>100000,"Medium","Low")) -> High
...

Sheet New_Sales_Data
A1: Order ID | B1: Product ID | C1: Product Name | D1: Category | E1: Region | F1: Sales Channel | G1: Sales Rep | H1: Order Date | I1: Units Sold | J1: Unit Price (₦) | K1: Discount (%) | L1: Payment Status | M1: Total Sales (₦) | N1: Net Revenue (₦) | O1: Revenue Tier
A2: ORD-1500 | B2: PKG-003 | C2: CrispBite Potato Chips 150g | D2: Snacks | E2: East | F2: Supermarket | G2: Chidi Nwosu | H2: 45450 | I2: 77 | J2: 420 | K2: 0.05 | L2: Pending | M2: 32340 | N2: 30723 | O2: Low
A3: ORD-1501 | B3: PKG-008 | C3: NutriMix Cereal Box 500g | D3: Breakfast | E3: Central | F3: Convenience Store | G3: Emeka Okafor | H3: 45473 | I3: 74 | J3: 2800 | K3: 0.08 | L3: Pending | M3: 207200 | N3: 190624 | O3: Medium
A4: ORD-1502 | B4: PKG-009 | C4: CrispBite Corn Chips 100g | D4: Snacks | E4: North | F4: Online | G4: Amara Osei | H4: 45457 | I4: 99 | J4: 280 | K4: 0.11 | L4: Paid | M4: 27720 | N4: 24670.8 | O4: Low
A5: ORD-1503 | B5: PKG-008 | C5: NutriMix Cereal Box 500g | D5: Breakfast | E5: South | F5: Supermarket | G5: Emeka Okafor | H5: 45462 | I5: 39 | J5: 2800 | K5: 0 | L5: Paid | M5: 109200 | N5: 109200 | O5: Medium
A6: ORD-1504 | B6: PKG-007 | C6: FreshSip Mango Juice 500ml | D6: Beverages | E6: South | F6: Wholesaler | G6: Tunde Bello | H6: 45467 | I6: 135 | J6: 650 | K6: 0 | L6: Pending | M6: 87750 | N6: 87750 | O6: Low
A7: ORD-1505 | B7: PKG-001 | C7: FreshSip Orange Juice 1L | D7: Beverages | E7: North | F7: Convenience Store | G7: Ngozi Eze | H7: 45470 | I7: 103 | J7: 990 | K7: 0.07 | L7: Paid | M7: 101970 | N7: 94832.1 | O7: Low
A8: ORD-1506 | B8: PKG-008 | C8: NutriMix Cereal Box 500g | D8: Breakfast | E8: South | F8: Wholesaler | G8: Tunde Bello | H8: 45451 | I8: 49 | J8: 2800 | K8: 0.11 | L8: Pending | M8: 137200 | N8: 122108 | O8: Medium
A9: ORD-1507 | B9: PKG-005 | C9: HealthPure Bottled Water 500ml | D9: Beverages | E9: South | F9: Convenience Store | G9: Emeka Okafor | H9: 45450 | I9: 189 | J9: 200 | K9: 0.12 | L9: Paid | M9: 37800 | N9: 33264 | O9: Low
A10: ORD-1508 | B10: PKG-002 | C10: NutriMix Granola Bar | D10: Snacks | E10: East | F10: Supermarket | G10: Chidi Nwosu | H10: 45456 | I10: 96 | J10: 350 | K10: 0.05 | L10: Pending | M10: 33600 | N10: 31920 | O10: Low
A11: ORD-1509 | B11: PKG-002 | C11: NutriMix Granola Bar | D11: Snacks | E11: Central | F11: Convenience Store | G11: Emeka Okafor | H11: 45448 | I11: 157 | J11: 350 | K11: 0.1 | L11: Pending | M11: 54950 | N11: 49455 | O11: Low
A12: ORD-1510 | B12: PKG-009 | C12: CrispBite Corn Chips 100g | D12: Snacks | E12: East | F12: Supermarket | G12: Ngozi Eze | H12: 45452 | I12: 97 | J12: 280 | K12: 0.08 | L12: Paid | M12: 27160 | N12: 24987.2 | O12: Low
A13: ORD-1511 | B13: PKG-010 | C13: GoldenBite Chocolate Cookies 150g | D13: Baked Goods | E13: South | F13: Online | G13: Amara Osei | H13: 45459 | I13: 80 | J13: 750 | K13: 0.15 | L13: Paid | M13: 60000 | N13: 51000 | O13: Low
... A1297: ORD-2795 | B1297: PKG-007 | C1297: FreshSip Mango Juice 500ml | D1297: Beverages | E1297: North | F1297: Online | G1297: Tunde Bello | H1297: 46157 | I1297: 235 | J1297: 650 | K1297: 0.08 | L1297: Paid | M1297: 152750 | N1297: 140530 | O1297: Medium

Sheet Combined_Data
A1: Order ID | B1: Product ID | C1: Product Name | D1: Category | E1: Region | F1: Sales Channel | G1: Sales Rep | H1: Order Date | I1: Units Sold | J1: Unit Price (₦) | K1: Discount (%) | L1: Payment Status | M1: Total Sales (₦) | N1: Net Revenue (₦) | O1: Revenue Tier
A2: ORD-1001 | B2: PKG-001 | C2: FreshSip Orange Juice 1L | D2: Beverages | E2: North | F2: Supermarket | G2: Amara Osei | H2: 45292 | I2: 337 | J2: 990 | K2: 0.12 | L2: Paid | M2: =Combined_Data!$I2*Combined_Data!$J2 -> 333630 | N2: =Combined_Data!$M2*(1-Combined_Data!$K2) -> 293594.4 | O2: =IF(Combined_Data!$N2>350000,"High",IF(Combined_Data!$N2>100000,"Medium","Low")) -> Medium
A3: ORD-1002 | B3: PKG-002 | C3: NutriMix Granola Bar | D3: Snacks | E3: South | F3: Wholesaler | G3: Tunde Bello | H3: 45293 | I3: 135 | J3: 350 | K3: 0 | L3: Pending | M3: =Combined_Data!$I3*Combined_Data!$J3 -> 47250 | N3: =Combined_Data!$M3*(1-Combined_Data!$K3) -> 47250 | O3: =IF(Combined_Data!$N3>350000,"High",IF(Combined_Data!$N3>100000,"Medium","Low")) -> Low
A4: ORD-1003 | B4: PKG-003 | C4: CrispBite Potato Chips 150g | D4: Snacks | E4: East | F4: Online | G4: Ngozi Eze | H4: 45294 | I4: 387 | J4: 420 | K4: 0 | L4: Paid | M4: =Combined_Data!$I4*Combined_Data!$J4 -> 162540 | N4: =Combined_Data!$M4*(1-Combined_Data!$K4) -> 162540 | O4: =IF(Combined_Data!$N4>350000,"High",IF(Combined_Data!$N4>100000,"Medium","Low")) -> Medium
A5: ORD-1004 | B5: PKG-004 | C5: DailyBrew Green Tea 25 bags | D5: Beverages | E5: West | F5: Convenience Store | G5: Emeka Okafor | H5: 45295 | I5: 389 | J5: 1200 | K5: 0.03 | L5: Paid | M5: =Combined_Data!$I5*Combined_Data!$J5 -> 466800 | N5: =Combined_Data!$M5*(1-Combined_Data!$K5) -> 452796 | O5: =IF(Combined_Data!$N5>350000,"High",IF(Combined_Data!$N5>100000,"Medium","Low")) -> High
A6: ORD-1005 | B6: PKG-005 | C6: HealthPure Bottled Water 500ml | D6: Beverages | E6: Central | F6: Pharmacy | G6: Fatima Musa | H6: 45296 | I6: 226 | J6: 200 | K6: 0 | L6: Pending | M6: =Combined_Data!$I6*Combined_Data!$J6 -> 45200 | N6: =Combined_Data!$M6*(1-Combined_Data!$K6) -> 45200 | O6: =IF(Combined_Data!$N6>350000,"High",IF(Combined_Data!$N6>100000,"Medium","Low")) -> Low
A7: ORD-1006 | B7: PKG-006 | C7: GoldenBite Biscuits 200g | D7: Baked Goods | E7: North | F7: Supermarket | G7: Chidi Nwosu | H7: 45297 | I7: 100 | J7: 895 | K7: 0 | L7: Paid | M7: 89500 | N7: =Combined_Data!$M7*(1-Combined_Data!$K7) -> 89500 | O7: =IF(Combined_Data!$N7>350000,"High",IF(Combined_Data!$N7>100000,"Medium","Low")) -> Low
A8: ORD-1007 | B8: PKG-007 | C8: FreshSip Mango Juice 500ml | D8: Beverages | E8: South | F8: Wholesaler | G8: Amara Osei | H8: 45298 | I8: 268 | J8: 650 | K8: 0.09 | L8: Pending | M8: =Combined_Data!$I8*Combined_Data!$J8 -> 174200 | N8: =Combined_Data!$M8*(1-Combined_Data!$K8) -> 158522 | O8: =IF(Combined_Data!$N8>350000,"High",IF(Combined_Data!$N8>100000,"Medium","Low")) -> Medium
A9: ORD-1008 | B9: PKG-008 | C9: NutriMix Cereal Box 500g | D9: Breakfast | E9: East | F9: Online | G9: Tunde Bello | H9: 45299 | I9: 376 | J9: 2800 | K9: 0 | L9: Paid | M9: =Combined_Data!$I9*Combined_Data!$J9 -> 1052800 | N9: =Combined_Data!$M9*(1-Combined_Data!$K9) -> 1052800 | O9: =IF(Combined_Data!$N9>350000,"High",IF(Combined_Data!$N9>100000,"Medium","Low")) -> High
A10: ORD-1009 | B10: PKG-009 | C10: CrispBite Corn Chips 100g | D10: Snacks | E10: West | F10: Convenience Store | G10: Ngozi Eze | H10: 45300 | I10: 289 | J10: 280 | K10: 0 | L10: Paid | M10: =Combined_Data!$I10*Combined_Data!$J10 -> 80920 | N10: =Combined_Data!$M10*(1-Combined_Data!$K10) -> 80920 | O10: =IF(Combined_Data!$N10>350000,"High",IF(Combined_Data!$N10>100000,"Medium","Low")) -> Low
A11: ORD-1010 | B11: PKG-010 | C11: GoldenBite Chocolate Cookies 150g | D11: Baked Goods | E11: Central | F11: Pharmacy | G11: Emeka Okafor | H11: 45301 | I11: 239 | J11: 750 | K11: 0.13 | L11: Pending | M11: =Combined_Data!$I11*Combined_Data!$J11 -> 179250 | N11: =Combined_Data!$M11*(1-Combined_Data!$K11) -> 155947.5 | O11: =IF(Combined_Data!$N11>350000,"High",IF(Combined_Data!$N11>100000,"Medium","Low")) -> Medium
A12: ORD-1011 | B12: PKG-001 | C12: FreshSip Orange Juice 1L | D12: Beverages | E12: North | F12: Supermarket | G12: Fatima Musa | H12: 45302 | I12: 13 | J12: 990 | K12: 0 | L12: Paid | M12: =Combined_Data!$I12*Combined_Data!$J12 -> 12870 | N12: =Combined_Data!$M12*(1-Combined_Data!$K12) -> 12870 | O12: =IF(Combined_Data!$N12>350000,"High",IF(Combined_Data!$N12>100000,"Medium","Low")) -> Low
A13: ORD-1012 | B13: PKG-002 | C13: NutriMix Granola Bar | D13: Snacks | E13: South | F13: Wholesaler | G13: Chidi Nwosu | H13: 45304 | I13: 91 | J13: 350 | K13: 0 | L13: Pending | M13: =Combined_Data!$I13*Combined_Data!$J13 -> 31850 | N13: =Combined_Data!$M13*(1-Combined_Data!$K13) -> 31850 | O13: =IF(Combined_Data!$N13>350000,"High",IF(Combined_Data!$N13>100000,"Medium","Low")) -> Low
A14: ORD-1013 | B14: PKG-003 | C14: CrispBite Potato Chips 150g | D14: Snacks | E14: East | F14: Online | G14: Amara Osei | H14: 45305 | I14: 184 | J14: 420 | K14: 0.05 | L14: Paid | M14: =Combined_Data!$I14*Combined_Data!$J14 -> 77280 | N14: =Combined_Data!$M14*(1-Combined_Data!$K14) -> 73416 | O14: =IF(Combined_Data!$N14>350000,"High",IF(Combined_Data!$N14>100000,"Medium","Low")) -> Low
A15: ORD-1014 | B15: PKG-004 | C15: DailyBrew Green Tea 25 bags | D15: Beverages | E15: West | F15: Convenience Store | G15: Tunde Bello | H15: 45306 | I15: 400 | J15: 1200 | K15: 0 | L15: Paid | M15: =Combined_Data!$I15*Combined_Data!$J15 -> 480000 | N15: =Combined_Data!$M15*(1-Combined_Data!$K15) -> 480000 | O15: =IF(Combined_Data!$N15>350000,"High",IF(Combined_Data!$N15>100000,"Medium","Low")) -> High
A16: ORD-1015 | B16: PKG-005 | C16: HealthPure Bottled Water 500ml | D16: Beverages | E16: Central | F16: Pharmacy | G16: Ngozi Eze | H16: 45307 | I16: 57 | J16: 200 | K16: 0 | L16: Pending | M16: =Combined_Data!$I16*Combined_Data!$J16 -> 11400 | N16: =Combined_Data!$M16*(1-Combined_Data!$K16) -> 11400 | O16: =IF(Combined_Data!$N16>350000,"High",IF(Combined_Data!$N16>100000,"Medium","Low")) -> Low
A17: ORD-1016 | B17: PKG-006 | C17: GoldenBite Biscuits 200g | D17: Baked Goods | E17: North | F17: Supermarket | G17: Emeka Okafor | H17: 45308 | I17: 193 | J17: 895 | K17: 0.1 | L17: Paid | M17: =Combined_Data!$I17*Combined_Data!$J17 -> 172735 | N17: =Combined_Data!$M17*(1-Combined_Data!$K17) -> 155461.5 | O17: =IF(Combined_Data!$N17>350000,"High",IF(Combined_Data!$N17>100000,"Medium","Low")) -> Medium
A18: ORD-1017 | B18: PKG-007 | C18: FreshSip Mango Juice 500ml | D18: Beverages | E18: South | F18: Wholesaler | G18: Fatima Musa | H18: 45309 | I18: 423 | J18: 650 | K18: 0 | L18: Pending | M18: =Combined_Data!$I18*Combined_Data!$J18 -> 274950 | N18: =Combined_Data!$M18*(1-Combined_Data!$K18) -> 274950 | O18: =IF(Combined_Data!$N18>350000,"High",IF(Combined_Data!$N18>100000,"Medium","Low")) -> Medium
A19: ORD-1018 | B19: PKG-008 | C19: NutriMix Cereal Box 500g | D19: Breakfast | E19: East | F19: Online | G19: Chidi Nwosu | H19: 45310 | I19: 245 | J19: 2800 | K19: 0 | L19: Paid | M19: =Combined_Data!$I19*Combined_Data!$J19 -> 686000 | N19: =Combined_Data!$M19*(1-Combined_Data!$K19) -> 686000 | O19: =IF(Combined_Data!$N19>350000,"High",IF(Combined_Data!$N19>100000,"Medium","Low")) -> High
... A23: ORD-1022 | B23: PKG-002 | C23: NutriMix Granola Bar | D23: Snacks | E23: South | F23: Wholesaler | G23: Emeka Okafor | H23: 45314 | I23: 305 | J23: 350 | K23: 0.03 | L23: Pending | M23: =Combined_Data!$I23*Combined_Data!$J23 -> 106750 | N23: =Combined_Data!$M23*(1-Combined_Data!$K23) -> 103547.5 | O23: =IF(Combined_Data!$N23>350000,"High",IF(Combined_Data!$N23>100000,"Medium","Low")) -> Medium
A24: ORD-1023 | B24: PKG-003 | C24: CrispBite Potato Chips 150g | D24: Snacks | E24: East | F24: Online | G24: Fatima Musa | H24: 45315 | I24: 150 | J24: 420 | K24: 0 | L24: Paid | M24: 63000 | N24: =Combined_Data!$M24*(1-Combined_Data!$K24) -> 63000 | O24: =IF(Combined_Data!$N24>350000,"High",IF(Combined_Data!$N24>100000,"Medium","Low")) -> Low
A25: ORD-1024 | B25: PKG-004 | C25: DailyBrew Green Tea 25 bags | D25: Beverages | E25: West | F25: Convenience Store | G25: Chidi Nwosu | H25: 45316 | I25: 158 | J25: 1200 | K25: 0 | L25: Paid | M25: =Combined_Data!$I25*Combined_Data!$J25 -> 189600 | N25: =Combined_Data!$M25*(1-Combined_Data!$K25) -> 189600 | O25: =IF(Combined_Data!$N25>350000,"High",IF(Combined_Data!$N25>100000,"Medium","Low")) -> Medium
A26: ORD-1025 | B26: PKG-005 | C26: HealthPure Bottled Water 500ml | D26: Beverages | E26: Central | F26: Pharmacy | G26: Amara Osei | H26: 45317 | I26: 447 | J26: 200 | K26: 0.03 | L26: Pending | M26: =Combined_Data!$I26*Combined_Data!$J26 -> 89400 | N26: =Combined_Data!$M26*(1-Combined_Data!$K26) -> 86718 | O26: =IF(Combined_Data!$N26>350000,"High",IF(Combined_Data!$N26>100000,"Medium","Low")) -> Low
A27: ORD-1026 | B27: PKG-006 | C27: GoldenBite Biscuits 200g | D27: Baked Goods | E27: North | F27: Supermarket | G27: Tunde Bello | H27: 45318 | I27: 152 | J27: 895 | K27: 0 | L27: Paid | M27: =Combined_Data!$I27*Combined_Data!$J27 -> 136040 | N27: =Combined_Data!$M27*(1-Combined_Data!$K27) -> 136040 | O27: =IF(Combined_Data!$N27>350000,"High",IF(Combined_Data!$N27>100000,"Medium","Low")) -> Medium
A28: ORD-1027 | B28: PKG-007 | C28: FreshSip Mango Juice 500ml | D28: Beverages | E28: South | F28: Wholesaler | G28: Ngozi Eze | H28: 45319 | I28: 437 | J28: 650 | K28: 0 | L28: Pending | M28: =Combined_Data!$I28*Combined_Data!$J28 -> 284050 | N28: =Combined_Data!$M28*(1-Combined_Data!$K28) -> 284050 | O28: =IF(Combined_Data!$N28>350000,"High",IF(Combined_Data!$N28>100000,"Medium","Low")) -> Medium
A29: ORD-1028 | B29: PKG-008 | C29: NutriMix Cereal Box 500g | D29: Breakfast | E29: East | F29: Online | G29: Emeka Okafor | H29: 45320 | I29: 199 | J29: 2800 | K29: 0.11 | L29: Paid | M29: =Combined_Data!$I29*Combined_Data!$J29 -> 557200 | N29: =Combined_Data!$M29*(1-Combined_Data!$K29) -> 495908 | O29: =IF(Combined_Data!$N29>350000,"High",IF(Combined_Data!$N29>100000,"Medium","Low")) -> High
A30: ORD-1029 | B30: PKG-009 | C30: CrispBite Corn Chips 100g | D30: Snacks | E30: West | F30: Convenience Store | G30: Fatima Musa | H30: 45321 | I30: 369 | J30: 280 | K30: 0 | L30: Paid | M30: =Combined_Data!$I30*Combined_Data!$J30 -> 103320 | N30: =Combined_Data!$M30*(1-Combined_Data!$K30) -> 103320 | O30: =IF(Combined_Data!$N30>350000,"High",IF(Combined_Data!$N30>100000,"Medium","Low")) -> Medium
A31: ORD-1030 | B31: PKG-010 | C31: GoldenBite Chocolate Cookies 150g | D31: Baked Goods | E31: Central | F31: Pharmacy | G31: Chidi Nwosu | H31: 45322 | I31: 341 | J31: 750 | K31: 0 | L31: Pending | M31: =Combined_Data!$I31*Combined_Data!$J31 -> 255750 | N31: =Combined_Data!$M31*(1-Combined_Data!$K31) -> 255750 | O31: =IF(Combined_Data!$N31>350000,"High",IF(Combined_Data!$N31>100000,"Medium","Low")) -> Medium
A32: ORD-1031 | B32: PKG-001 | C32: FreshSip Orange Juice 1L | D32: Beverages | E32: North | F32: Supermarket | G32: Amara Osei | H32: 45323 | I32: 335 | J32: 990 | K32: 0.11 | L32: Paid | M32: =Combined_Data!$I32*Combined_Data!$J32 -> 331650 | N32: =Combined_Data!$M32*(1-Combined_Data!$K32) -> 295168.5 | O32: =IF(Combined_Data!$N32>350000,"High",IF(Combined_Data!$N32>100000,"Medium","Low")) -> Medium
A33: ORD-1032 | B33: PKG-002 | C33: NutriMix Granola Bar | D33: Snacks | E33: South | F33: Wholesaler | G33: Tunde Bello | H33: 45324 | I33: 93 | J33: 350 | K33: 0 | L33: Pending | M33: =Combined_Data!$I33*Combined_Data!$J33 -> 32550 | N33: =Combined_Data!$M33*(1-Combined_Data!$K33) -> 32550 | O33: =IF(Combined_Data!$N33>350000,"High",IF(Combined_Data!$N33>100000,"Medium","Low")) -> Low
A34: ORD-1033 | B34: PKG-003 | C34: CrispBite Potato Chips 150g | D34: Snacks | E34: East | F34: Online | G34: Ngozi Eze | H34: 45325 | I34: 148 | J34: 420 | K34: 0 | L34: Paid | M34: =Combined_Data!$I34*Combined_Data!$J34 -> 62160 | N34: =Combined_Data!$M34*(1-Combined_Data!$K34) -> 62160 | O34: =IF(Combined_Data!$N34>350000,"High",IF(Combined_Data!$N34>100000,"Medium","Low")) -> Low
A35: ORD-1034 | B35: PKG-004 | C35: DailyBrew Green Tea 25 bags | D35: Beverages | E35: West | F35: Convenience Store | G35: Emeka Okafor | H35: 45326 | I35: 337 | J35: 1200 | K35: 0.05 | L35: Paid | M35: =Combined_Data!$I35*Combined_Data!$J35 -> 404400 | N35: =Combined_Data!$M35*(1-Combined_Data!$K35) -> 384180 | O35: =IF(Combined_Data!$N35>350000,"High",IF(Combined_Data!$N35>100000,"Medium","Low")) -> High
A36: ORD-1035 | B36: PKG-005 | C36: HealthPure Bottled Water 500ml | D36: Beverages | E36: Central | F36: Pharmacy | G36: Fatima Musa | H36: 45327 | I36: 176 | J36: 200 | K36: 0 | L36: Pending | M36: =Combined_Data!$I36*Combined_Data!$J36 -> 35200 | N36: =Combined_Data!$M36*(1-Combined_Data!$K36) -> 35200 | O36: =IF(Combined_Data!$N36>350000,"High",IF(Combined_Data!$N36>100000,"Medium","Low")) -> Low
... A39: ORD-1038 | B39: PKG-008 | C39: NutriMix Cereal Box 500g | D39: Breakfast | E39: East | F39: Online | G39: Tunde Bello | H39: 45330 | I39: 147 | J39: 2800 | K39: 0 | L39: Paid | M39: =Combined_Data!$I39*Combined_Data!$J39 -> 411600 | N39: =Combined_Data!$M39*(1-Combined_Data!$K39) -> 411600 | O39: =IF(Combined_Data!$N39>350000,"High",IF(Combined_Data!$N39>100000,"Medium","Low")) -> High
A40: ORD-1039 | B40: PKG-009 | C40: CrispBite Corn Chips 100g | D40: Snacks | E40: West | F40: Convenience Store | G40: Ngozi Eze | H40: 45331 | I40: 63 | J40: 280 | K40: 0 | L40: Paid | M40: 17640 | N40: =Combined_Data!$M40*(1-Combined_Data!$K40) -> 17640 | O40: =IF(Combined_Data!$N40>350000,"High",IF(Combined_Data!$N40>100000,"Medium","Low")) -> Low
A41: ORD-1040 | B41: PKG-010 | C41: GoldenBite Chocolate Cookies 150g | D41: Baked Goods | E41: Central | F41: Pharmacy | G41: Emeka Okafor | H41: 45332 | I41: 458 | J41: 750 | K41: 0.05 | L41: Pending | M41: =Combined_Data!$I41*Combined_Data!$J41 -> 343500 | N41: =Combined_Data!$M41*(1-Combined_Data!$K41) -> 326325 | O41: =IF(Combined_Data!$N41>350000,"High",IF(Combined_Data!$N41>100000,"Medium","Low")) -> Medium
A42: ORD-1041 | B42: PKG-001 | C42: FreshSip Orange Juice 1L | D42: Beverages | E42: North | F42: Supermarket | G42: Fatima Musa | H42: 45333 | I42: 265 | J42: 990 | K42: 0 | L42: Paid | M42: =Combined_Data!$I42*Combined_Data!$J42 -> 262350 | N42: =Combined_Data!$M42*(1-Combined_Data!$K42) -> 262350 | O42: =IF(Combined_Data!$N42>350000,"High",IF(Combined_Data!$N42>100000,"Medium","Low")) -> Medium
A43: ORD-1042 | B43: PKG-002 | C43: NutriMix Granola Bar | D43: Snacks | E43: South | F43: Wholesaler | G43: Chidi Nwosu | H43: 45334 | I43: 478 | J43: 350 | K43: 0 | L43: Pending | M43: =Combined_Data!$I43*Combined_Data!$J43 -> 167300 | N43: =Combined_Data!$M43*(1-Combined_Data!$K43) -> 167300 | O43: =IF(Combined_Data!$N43>350000,"High",IF(Combined_Data!$N43>100000,"Medium","Low")) -> Medium
A44: ORD-1043 | B44: PKG-003 | C44: CrispBite Potato Chips 150g | D44: Snacks | E44: East | F44: Online | G44: Amara Osei | H44: 45335 | I44: 83 | J44: 420 | K44: 0.05 | L44: Paid | M44: =Combined_Data!$I44*Combined_Data!$J44 -> 34860 | N44: =Combined_Data!$M44*(1-Combined_Data!$K44) -> 33117 | O44: =IF(Combined_Data!$N44>350000,"High",IF(Combined_Data!$N44>100000,"Medium","Low")) -> Low
A45: ORD-1044 | B45: PKG-004 | C45: DailyBrew Green Tea 25 bags | D45: Beverages | E45: West | F45: Convenience Store | G45: Tunde Bello | H45: 45336 | I45: 297 | J45: 1200 | K45: 0 | L45: Paid | M45: =Combined_Data!$I45*Combined_Data!$J45 -> 356400 | N45: =Combined_Data!$M45*(1-Combined_Data!$K45) -> 356400 | O45: =IF(Combined_Data!$N45>350000,"High",IF(Combined_Data!$N45>100000,"Medium","Low")) -> High
...

Sheet Pivot Tables
C5: 1. Monthly revenue across all three years | J5: 3. Which product category contributes the most to total revenue — and which contributes the least? | Q5: 5. Which sales channel generates the highest total paid revenue — and which is the weakest performer?
C7: Payment Status | D7: Paid | J7: Payment Status | K7: Paid | Q7: Payment Status | R7: Paid
C9: Sum of Net Revenue (₦) | D9: Column Labels | J9: Row Labels | K9: Sum of Net Revenue (₦) | Q9: Row Labels | R9: Sum of Net Revenue (₦)
C10: Row Labels | D10: 2024 | E10: 2025 | F10: 2026 | G10: Grand Total | J10: Baked Goods | K10: 25889411 | Q10: Online | R10: 28690898
C11: Jan | D11: 5108949.5 | E11: 4766789.5 | F11: 5244011.8 | G11: 15119751 | J11: Beverages | K11: 41917738 | Q11: Supermarket | R11: 25782802
C12: Feb | D12: 4080558.6 | E12: 5661650.4 | F12: 5333289 | G12: 15075498 | J12: Breakfast | K12: 31746372 | Q12: Convenience Store | R12: 22826856
C13: Mar | D13: 4918146.6 | E13: 5851903.3 | F13: 5829287.8 | G13: 16599338 | J13: Snacks | K13: 20595780 | Q13: Wholesaler | R13: 22530255
C14: Apr | D14: 5978014.8 | E14: 4488471.2 | F14: 5604900.2 | G14: 16071386 | J14: Grand Total | K14: 1.201493e+08 | Q14: Pharmacy | R14: 20318491
C15: May | D15: 33880 | E15: 2758113.4 | F15: 2959197.8 | G15: 5751191.2 | Q15: Grand Total | R15: 1.201493e+08
C16: Jun | D16: 4224813.8 | E16: 6315554.6 | G16: 10540368
C17: Jul | D17: 4074311.8 | E17: 5084961.1 | G17: 9159272.9
C18: Aug | D18: 3302361 | E18: 4220503.1 | G18: 7522864.1
C19: Sep | D19: 2903069.3 | E19: 4278758.1 | G19: 7181827.4
C20: Oct | D20: 3353023.2 | E20: 4379108.2 | G20: 7732131.4
C21: Nov | D21: 2909902.6 | E21: 4129634.8 | G21: 7039537.4
C22: Dec | D22: 996842.5 | E22: 1359293.1 | G22: 2356135.6
C23: Grand Total | D23: 41883874 | E23: 53294741 | F23: 24970687 | G23: 1.201493e+08
J25: 4. Which five products are driving the most revenue for NouraMart | Q25: 6. How do we compare sales rep performance side by side using a pivot table?
C27: 2. Total paid revenue per region | J27: Payment Status | K27: Paid | Q27: Payment Status | R27: Paid
C29: Payment Status | D29: Paid | J29: Row Labels | K29: Sum of Net Revenue (₦) | Q29: Row Labels | R29: Sum of Net Revenue (₦)
J30: NutriMix Cereal Box 500g | K30: 31746372 | Q30: Amara Osei | R30: 16630815
C31: Row Labels | D31: Sum of Net Revenue (₦) | J31: DailyBrew Green Tea 25 bags | K31: 16727004 | Q31: Chidi Nwosu | R31: 19592694
C32: East | D32: 30799215 | J32: GoldenBite Biscuits 200g | K32: 13868401 | Q32: Emeka Okafor | R32: 18952286
C33: North | D33: 26072316 | J33: FreshSip Orange Juice 1L | K33: 11949013 | Q33: Fatima Musa | R33: 17690430
C34: West | D34: 24112143 | J34: GoldenBite Chocolate Cookies 150g | K34: 8343457.5 | Q34: Ngozi Eze | R34: 18976359
C35: Central | D35: 20957379 | J35: Grand Total | K35: 82634247 | Q35: Tunde Bello | R35: 28306718
C36: South | D36: 18208248 | Q36: Grand Total | R36: 1.201493e+08
C37: Grand Total | D37: 1.201493e+08
J38: Row Labels | K38: Sum of Net Revenue (₦) | L38: Remainder
J39: GoldenBite Chocolate Cookies 150g | K39: 8343457.5 | L39: =31746372-K39 -> 23402914
J40: FreshSip Orange Juice 1L | K40: 11949013 | L40: =31746372-K40 -> 19797359
J41: GoldenBite Biscuits 200g | K41: 13868401 | L41: =31746372-K41 -> 17877971
J42: DailyBrew Green Tea 25 bags | K42: 16727004 | L42: =31746372-K42 -> 15019368
J43: NutriMix Cereal Box 500g | K43: 31746372 | L43: =31746372-K43 -> 0
J44: Grand Total | K44: 82634247

Sheet KPIs
A1: KPI | B1: Answer
A2: Total Net Revenue | B2: =SUMIF(data[Payment Status], "Paid", data[Net Revenue (₦)]) -> 1.201493e+08
A3: Total Orders | B3: =COUNTIF(data[Payment Status], "Paid") -> 910
A4: Average Order Value | B4: =AVERAGEIF(data[Payment Status],"Paid",data[Net Revenue (₦)]) -> 132032.2
A5: Top Region | B5: =INDEX(data[Region],MATCH(_xlfn.MAXIFS(data[Net Revenue (₦)],data[Payment Status],"Paid"),data[Net Revenue (₦)],0)) -> East
A6: Top Product | B6: =INDEX(data[Product Name],MATCH(_xlfn.MAXIFS(data[Net Revenue (₦)],data[Payment Status],"Paid"),data[Net Revenue (₦)],0)) -> NutriMix Cereal Box 500g

Sheet Dashboard
